{
 "cells": [
  {
   "cell_type": "code",
   "execution_count": 45,
   "id": "284f42c0",
   "metadata": {},
   "outputs": [],
   "source": [
    "import numpy as np\n",
    "import pandas as pd\n",
    "from sklearn.linear_model import LogisticRegression, LinearRegression\n",
    "from sklearn.tree import DecisionTreeClassifier, DecisionTreeRegressor\n",
    "from sklearn.ensemble import RandomForestClassifier\n",
    "from sklearn.model_selection import train_test_split, KFold, cross_val_score\n",
    "from sklearn.preprocessing import LabelEncoder\n",
    "from sklearn.metrics import r2_score, mean_squared_error"
   ]
  },
  {
   "cell_type": "code",
   "execution_count": 46,
   "id": "253b43b7",
   "metadata": {},
   "outputs": [],
   "source": [
    "data=pd.read_csv('data.csv')"
   ]
  },
  {
   "cell_type": "code",
   "execution_count": 47,
   "id": "54d24fc6",
   "metadata": {},
   "outputs": [
    {
     "name": "stdout",
     "output_type": "stream",
     "text": [
      "Classifier: LogisticRegression\n",
      "Cross-Validation Scores:\n",
      "Mean: 0.96\n",
      "Standard Deviation: 0.038873012632301994\n",
      "\n",
      "Classifier: DecisionTreeClassifier\n",
      "Cross-Validation Scores:\n",
      "Mean: 0.9533333333333334\n",
      "Standard Deviation: 0.039999999999999994\n",
      "\n",
      "Classifier: RandomForestClassifier\n",
      "Cross-Validation Scores:\n",
      "Mean: 0.9533333333333334\n",
      "Standard Deviation: 0.039999999999999994\n",
      "\n"
     ]
    },
    {
     "ename": "ValueError",
     "evalue": "\nAll the 5 fits failed.\nIt is very likely that your model is misconfigured.\nYou can try to debug the error by setting error_score='raise'.\n\nBelow are more details about the failures:\n--------------------------------------------------------------------------------\n5 fits failed with the following error:\nTraceback (most recent call last):\n  File \"C:\\ProgramData\\anaconda3\\Lib\\site-packages\\sklearn\\model_selection\\_validation.py\", line 732, in _fit_and_score\n    estimator.fit(X_train, y_train, **fit_params)\n  File \"C:\\ProgramData\\anaconda3\\Lib\\site-packages\\sklearn\\base.py\", line 1151, in wrapper\n    return fit_method(estimator, *args, **kwargs)\n           ^^^^^^^^^^^^^^^^^^^^^^^^^^^^^^^^^^^^^^\n  File \"C:\\ProgramData\\anaconda3\\Lib\\site-packages\\sklearn\\linear_model\\_base.py\", line 678, in fit\n    X, y = self._validate_data(\n           ^^^^^^^^^^^^^^^^^^^^\n  File \"C:\\ProgramData\\anaconda3\\Lib\\site-packages\\sklearn\\base.py\", line 621, in _validate_data\n    X, y = check_X_y(X, y, **check_params)\n           ^^^^^^^^^^^^^^^^^^^^^^^^^^^^^^^\n  File \"C:\\ProgramData\\anaconda3\\Lib\\site-packages\\sklearn\\utils\\validation.py\", line 1163, in check_X_y\n    y = _check_y(y, multi_output=multi_output, y_numeric=y_numeric, estimator=estimator)\n        ^^^^^^^^^^^^^^^^^^^^^^^^^^^^^^^^^^^^^^^^^^^^^^^^^^^^^^^^^^^^^^^^^^^^^^^^^^^^^^^^\n  File \"C:\\ProgramData\\anaconda3\\Lib\\site-packages\\sklearn\\utils\\validation.py\", line 1188, in _check_y\n    y = y.astype(np.float64)\n        ^^^^^^^^^^^^^^^^^^^^\nValueError: could not convert string to float: 'Class1'\n",
     "output_type": "error",
     "traceback": [
      "\u001b[1;31m---------------------------------------------------------------------------\u001b[0m",
      "\u001b[1;31mValueError\u001b[0m                                Traceback (most recent call last)",
      "Cell \u001b[1;32mIn[47], line 12\u001b[0m\n\u001b[0;32m      9\u001b[0m      \u001b[38;5;28mprint\u001b[39m()\n\u001b[0;32m     11\u001b[0m \u001b[38;5;28;01mfor\u001b[39;00m reg \u001b[38;5;129;01min\u001b[39;00m regressors:\n\u001b[1;32m---> 12\u001b[0m      scores \u001b[38;5;241m=\u001b[39m cross_val_score(reg, X, y, cv\u001b[38;5;241m=\u001b[39mkfold, scoring\u001b[38;5;241m=\u001b[39m\u001b[38;5;124m'\u001b[39m\u001b[38;5;124mneg_mean_squared_error\u001b[39m\u001b[38;5;124m'\u001b[39m)\n\u001b[0;32m     13\u001b[0m      \u001b[38;5;28mprint\u001b[39m(\u001b[38;5;124mf\u001b[39m\u001b[38;5;124m\"\u001b[39m\u001b[38;5;124mRegressor: \u001b[39m\u001b[38;5;132;01m{\u001b[39;00mreg\u001b[38;5;241m.\u001b[39m\u001b[38;5;18m__class__\u001b[39m\u001b[38;5;241m.\u001b[39m\u001b[38;5;18m__name__\u001b[39m\u001b[38;5;132;01m}\u001b[39;00m\u001b[38;5;124m\"\u001b[39m)\n\u001b[0;32m     14\u001b[0m      \u001b[38;5;28mprint\u001b[39m(\u001b[38;5;124m\"\u001b[39m\u001b[38;5;124mCross-Validation Scores:\u001b[39m\u001b[38;5;124m\"\u001b[39m)\n",
      "File \u001b[1;32mC:\\ProgramData\\anaconda3\\Lib\\site-packages\\sklearn\\model_selection\\_validation.py:562\u001b[0m, in \u001b[0;36mcross_val_score\u001b[1;34m(estimator, X, y, groups, scoring, cv, n_jobs, verbose, fit_params, pre_dispatch, error_score)\u001b[0m\n\u001b[0;32m    559\u001b[0m \u001b[38;5;66;03m# To ensure multimetric format is not supported\u001b[39;00m\n\u001b[0;32m    560\u001b[0m scorer \u001b[38;5;241m=\u001b[39m check_scoring(estimator, scoring\u001b[38;5;241m=\u001b[39mscoring)\n\u001b[1;32m--> 562\u001b[0m cv_results \u001b[38;5;241m=\u001b[39m cross_validate(\n\u001b[0;32m    563\u001b[0m     estimator\u001b[38;5;241m=\u001b[39mestimator,\n\u001b[0;32m    564\u001b[0m     X\u001b[38;5;241m=\u001b[39mX,\n\u001b[0;32m    565\u001b[0m     y\u001b[38;5;241m=\u001b[39my,\n\u001b[0;32m    566\u001b[0m     groups\u001b[38;5;241m=\u001b[39mgroups,\n\u001b[0;32m    567\u001b[0m     scoring\u001b[38;5;241m=\u001b[39m{\u001b[38;5;124m\"\u001b[39m\u001b[38;5;124mscore\u001b[39m\u001b[38;5;124m\"\u001b[39m: scorer},\n\u001b[0;32m    568\u001b[0m     cv\u001b[38;5;241m=\u001b[39mcv,\n\u001b[0;32m    569\u001b[0m     n_jobs\u001b[38;5;241m=\u001b[39mn_jobs,\n\u001b[0;32m    570\u001b[0m     verbose\u001b[38;5;241m=\u001b[39mverbose,\n\u001b[0;32m    571\u001b[0m     fit_params\u001b[38;5;241m=\u001b[39mfit_params,\n\u001b[0;32m    572\u001b[0m     pre_dispatch\u001b[38;5;241m=\u001b[39mpre_dispatch,\n\u001b[0;32m    573\u001b[0m     error_score\u001b[38;5;241m=\u001b[39merror_score,\n\u001b[0;32m    574\u001b[0m )\n\u001b[0;32m    575\u001b[0m \u001b[38;5;28;01mreturn\u001b[39;00m cv_results[\u001b[38;5;124m\"\u001b[39m\u001b[38;5;124mtest_score\u001b[39m\u001b[38;5;124m\"\u001b[39m]\n",
      "File \u001b[1;32mC:\\ProgramData\\anaconda3\\Lib\\site-packages\\sklearn\\utils\\_param_validation.py:211\u001b[0m, in \u001b[0;36mvalidate_params.<locals>.decorator.<locals>.wrapper\u001b[1;34m(*args, **kwargs)\u001b[0m\n\u001b[0;32m    205\u001b[0m \u001b[38;5;28;01mtry\u001b[39;00m:\n\u001b[0;32m    206\u001b[0m     \u001b[38;5;28;01mwith\u001b[39;00m config_context(\n\u001b[0;32m    207\u001b[0m         skip_parameter_validation\u001b[38;5;241m=\u001b[39m(\n\u001b[0;32m    208\u001b[0m             prefer_skip_nested_validation \u001b[38;5;129;01mor\u001b[39;00m global_skip_validation\n\u001b[0;32m    209\u001b[0m         )\n\u001b[0;32m    210\u001b[0m     ):\n\u001b[1;32m--> 211\u001b[0m         \u001b[38;5;28;01mreturn\u001b[39;00m func(\u001b[38;5;241m*\u001b[39margs, \u001b[38;5;241m*\u001b[39m\u001b[38;5;241m*\u001b[39mkwargs)\n\u001b[0;32m    212\u001b[0m \u001b[38;5;28;01mexcept\u001b[39;00m InvalidParameterError \u001b[38;5;28;01mas\u001b[39;00m e:\n\u001b[0;32m    213\u001b[0m     \u001b[38;5;66;03m# When the function is just a wrapper around an estimator, we allow\u001b[39;00m\n\u001b[0;32m    214\u001b[0m     \u001b[38;5;66;03m# the function to delegate validation to the estimator, but we replace\u001b[39;00m\n\u001b[0;32m    215\u001b[0m     \u001b[38;5;66;03m# the name of the estimator by the name of the function in the error\u001b[39;00m\n\u001b[0;32m    216\u001b[0m     \u001b[38;5;66;03m# message to avoid confusion.\u001b[39;00m\n\u001b[0;32m    217\u001b[0m     msg \u001b[38;5;241m=\u001b[39m re\u001b[38;5;241m.\u001b[39msub(\n\u001b[0;32m    218\u001b[0m         \u001b[38;5;124mr\u001b[39m\u001b[38;5;124m\"\u001b[39m\u001b[38;5;124mparameter of \u001b[39m\u001b[38;5;124m\\\u001b[39m\u001b[38;5;124mw+ must be\u001b[39m\u001b[38;5;124m\"\u001b[39m,\n\u001b[0;32m    219\u001b[0m         \u001b[38;5;124mf\u001b[39m\u001b[38;5;124m\"\u001b[39m\u001b[38;5;124mparameter of \u001b[39m\u001b[38;5;132;01m{\u001b[39;00mfunc\u001b[38;5;241m.\u001b[39m\u001b[38;5;18m__qualname__\u001b[39m\u001b[38;5;132;01m}\u001b[39;00m\u001b[38;5;124m must be\u001b[39m\u001b[38;5;124m\"\u001b[39m,\n\u001b[0;32m    220\u001b[0m         \u001b[38;5;28mstr\u001b[39m(e),\n\u001b[0;32m    221\u001b[0m     )\n",
      "File \u001b[1;32mC:\\ProgramData\\anaconda3\\Lib\\site-packages\\sklearn\\model_selection\\_validation.py:328\u001b[0m, in \u001b[0;36mcross_validate\u001b[1;34m(estimator, X, y, groups, scoring, cv, n_jobs, verbose, fit_params, pre_dispatch, return_train_score, return_estimator, return_indices, error_score)\u001b[0m\n\u001b[0;32m    308\u001b[0m parallel \u001b[38;5;241m=\u001b[39m Parallel(n_jobs\u001b[38;5;241m=\u001b[39mn_jobs, verbose\u001b[38;5;241m=\u001b[39mverbose, pre_dispatch\u001b[38;5;241m=\u001b[39mpre_dispatch)\n\u001b[0;32m    309\u001b[0m results \u001b[38;5;241m=\u001b[39m parallel(\n\u001b[0;32m    310\u001b[0m     delayed(_fit_and_score)(\n\u001b[0;32m    311\u001b[0m         clone(estimator),\n\u001b[1;32m   (...)\u001b[0m\n\u001b[0;32m    325\u001b[0m     \u001b[38;5;28;01mfor\u001b[39;00m train, test \u001b[38;5;129;01min\u001b[39;00m indices\n\u001b[0;32m    326\u001b[0m )\n\u001b[1;32m--> 328\u001b[0m _warn_or_raise_about_fit_failures(results, error_score)\n\u001b[0;32m    330\u001b[0m \u001b[38;5;66;03m# For callable scoring, the return type is only know after calling. If the\u001b[39;00m\n\u001b[0;32m    331\u001b[0m \u001b[38;5;66;03m# return type is a dictionary, the error scores can now be inserted with\u001b[39;00m\n\u001b[0;32m    332\u001b[0m \u001b[38;5;66;03m# the correct key.\u001b[39;00m\n\u001b[0;32m    333\u001b[0m \u001b[38;5;28;01mif\u001b[39;00m \u001b[38;5;28mcallable\u001b[39m(scoring):\n",
      "File \u001b[1;32mC:\\ProgramData\\anaconda3\\Lib\\site-packages\\sklearn\\model_selection\\_validation.py:414\u001b[0m, in \u001b[0;36m_warn_or_raise_about_fit_failures\u001b[1;34m(results, error_score)\u001b[0m\n\u001b[0;32m    407\u001b[0m \u001b[38;5;28;01mif\u001b[39;00m num_failed_fits \u001b[38;5;241m==\u001b[39m num_fits:\n\u001b[0;32m    408\u001b[0m     all_fits_failed_message \u001b[38;5;241m=\u001b[39m (\n\u001b[0;32m    409\u001b[0m         \u001b[38;5;124mf\u001b[39m\u001b[38;5;124m\"\u001b[39m\u001b[38;5;130;01m\\n\u001b[39;00m\u001b[38;5;124mAll the \u001b[39m\u001b[38;5;132;01m{\u001b[39;00mnum_fits\u001b[38;5;132;01m}\u001b[39;00m\u001b[38;5;124m fits failed.\u001b[39m\u001b[38;5;130;01m\\n\u001b[39;00m\u001b[38;5;124m\"\u001b[39m\n\u001b[0;32m    410\u001b[0m         \u001b[38;5;124m\"\u001b[39m\u001b[38;5;124mIt is very likely that your model is misconfigured.\u001b[39m\u001b[38;5;130;01m\\n\u001b[39;00m\u001b[38;5;124m\"\u001b[39m\n\u001b[0;32m    411\u001b[0m         \u001b[38;5;124m\"\u001b[39m\u001b[38;5;124mYou can try to debug the error by setting error_score=\u001b[39m\u001b[38;5;124m'\u001b[39m\u001b[38;5;124mraise\u001b[39m\u001b[38;5;124m'\u001b[39m\u001b[38;5;124m.\u001b[39m\u001b[38;5;130;01m\\n\u001b[39;00m\u001b[38;5;130;01m\\n\u001b[39;00m\u001b[38;5;124m\"\u001b[39m\n\u001b[0;32m    412\u001b[0m         \u001b[38;5;124mf\u001b[39m\u001b[38;5;124m\"\u001b[39m\u001b[38;5;124mBelow are more details about the failures:\u001b[39m\u001b[38;5;130;01m\\n\u001b[39;00m\u001b[38;5;132;01m{\u001b[39;00mfit_errors_summary\u001b[38;5;132;01m}\u001b[39;00m\u001b[38;5;124m\"\u001b[39m\n\u001b[0;32m    413\u001b[0m     )\n\u001b[1;32m--> 414\u001b[0m     \u001b[38;5;28;01mraise\u001b[39;00m \u001b[38;5;167;01mValueError\u001b[39;00m(all_fits_failed_message)\n\u001b[0;32m    416\u001b[0m \u001b[38;5;28;01melse\u001b[39;00m:\n\u001b[0;32m    417\u001b[0m     some_fits_failed_message \u001b[38;5;241m=\u001b[39m (\n\u001b[0;32m    418\u001b[0m         \u001b[38;5;124mf\u001b[39m\u001b[38;5;124m\"\u001b[39m\u001b[38;5;130;01m\\n\u001b[39;00m\u001b[38;5;132;01m{\u001b[39;00mnum_failed_fits\u001b[38;5;132;01m}\u001b[39;00m\u001b[38;5;124m fits failed out of a total of \u001b[39m\u001b[38;5;132;01m{\u001b[39;00mnum_fits\u001b[38;5;132;01m}\u001b[39;00m\u001b[38;5;124m.\u001b[39m\u001b[38;5;130;01m\\n\u001b[39;00m\u001b[38;5;124m\"\u001b[39m\n\u001b[0;32m    419\u001b[0m         \u001b[38;5;124m\"\u001b[39m\u001b[38;5;124mThe score on these train-test partitions for these parameters\u001b[39m\u001b[38;5;124m\"\u001b[39m\n\u001b[1;32m   (...)\u001b[0m\n\u001b[0;32m    423\u001b[0m         \u001b[38;5;124mf\u001b[39m\u001b[38;5;124m\"\u001b[39m\u001b[38;5;124mBelow are more details about the failures:\u001b[39m\u001b[38;5;130;01m\\n\u001b[39;00m\u001b[38;5;132;01m{\u001b[39;00mfit_errors_summary\u001b[38;5;132;01m}\u001b[39;00m\u001b[38;5;124m\"\u001b[39m\n\u001b[0;32m    424\u001b[0m     )\n",
      "\u001b[1;31mValueError\u001b[0m: \nAll the 5 fits failed.\nIt is very likely that your model is misconfigured.\nYou can try to debug the error by setting error_score='raise'.\n\nBelow are more details about the failures:\n--------------------------------------------------------------------------------\n5 fits failed with the following error:\nTraceback (most recent call last):\n  File \"C:\\ProgramData\\anaconda3\\Lib\\site-packages\\sklearn\\model_selection\\_validation.py\", line 732, in _fit_and_score\n    estimator.fit(X_train, y_train, **fit_params)\n  File \"C:\\ProgramData\\anaconda3\\Lib\\site-packages\\sklearn\\base.py\", line 1151, in wrapper\n    return fit_method(estimator, *args, **kwargs)\n           ^^^^^^^^^^^^^^^^^^^^^^^^^^^^^^^^^^^^^^\n  File \"C:\\ProgramData\\anaconda3\\Lib\\site-packages\\sklearn\\linear_model\\_base.py\", line 678, in fit\n    X, y = self._validate_data(\n           ^^^^^^^^^^^^^^^^^^^^\n  File \"C:\\ProgramData\\anaconda3\\Lib\\site-packages\\sklearn\\base.py\", line 621, in _validate_data\n    X, y = check_X_y(X, y, **check_params)\n           ^^^^^^^^^^^^^^^^^^^^^^^^^^^^^^^\n  File \"C:\\ProgramData\\anaconda3\\Lib\\site-packages\\sklearn\\utils\\validation.py\", line 1163, in check_X_y\n    y = _check_y(y, multi_output=multi_output, y_numeric=y_numeric, estimator=estimator)\n        ^^^^^^^^^^^^^^^^^^^^^^^^^^^^^^^^^^^^^^^^^^^^^^^^^^^^^^^^^^^^^^^^^^^^^^^^^^^^^^^^\n  File \"C:\\ProgramData\\anaconda3\\Lib\\site-packages\\sklearn\\utils\\validation.py\", line 1188, in _check_y\n    y = y.astype(np.float64)\n        ^^^^^^^^^^^^^^^^^^^^\nValueError: could not convert string to float: 'Class1'\n"
     ]
    }
   ],
   "source": [
    "kfold = KFold(n_splits=5, shuffle=True, random_state=42)\n",
    "\n",
    "for clf in classifiers:\n",
    "     scores = cross_val_score(clf, X, y, cv=kfold)\n",
    "     print(f\"Classifier: {clf.__class__.__name__}\")\n",
    "     print(\"Cross-Validation Scores:\")\n",
    "     print(\"Mean:\", scores.mean())\n",
    "     print(\"Standard Deviation:\", scores.std())\n",
    "     print()\n",
    "\n",
    "for reg in regressors:\n",
    "     scores = cross_val_score(reg, X, y, cv=kfold, scoring='neg_mean_squared_error')\n",
    "     print(f\"Regressor: {reg.__class__.__name__}\")\n",
    "     print(\"Cross-Validation Scores:\")\n",
    "     print(\"Mean:\", -scores.mean())\n",
    "     print(\"Standard Deviation:\", scores.std())\n",
    "     print()\n",
    "     \n",
    "     \n",
    "\n",
    "\n",
    "\n"
   ]
  },
  {
   "cell_type": "code",
   "execution_count": null,
   "id": "8077e063",
   "metadata": {},
   "outputs": [],
   "source": []
  },
  {
   "cell_type": "code",
   "execution_count": null,
   "id": "e9e985eb",
   "metadata": {},
   "outputs": [],
   "source": []
  },
  {
   "cell_type": "code",
   "execution_count": null,
   "id": "df1d0dc5",
   "metadata": {},
   "outputs": [],
   "source": [
    "\n"
   ]
  },
  {
   "cell_type": "code",
   "execution_count": null,
   "id": "bd9a1970",
   "metadata": {},
   "outputs": [],
   "source": [
    "\n"
   ]
  },
  {
   "cell_type": "code",
   "execution_count": null,
   "id": "2cd8568a",
   "metadata": {},
   "outputs": [],
   "source": []
  }
 ],
 "metadata": {
  "kernelspec": {
   "display_name": "Python 3 (ipykernel)",
   "language": "python",
   "name": "python3"
  },
  "language_info": {
   "codemirror_mode": {
    "name": "ipython",
    "version": 3
   },
   "file_extension": ".py",
   "mimetype": "text/x-python",
   "name": "python",
   "nbconvert_exporter": "python",
   "pygments_lexer": "ipython3",
   "version": "3.11.5"
  }
 },
 "nbformat": 4,
 "nbformat_minor": 5
}
